Workbook

Sheet Funnel_Data
A1: CUSTOMER JOURNEY & FUNNEL ANALYSIS — Raw Data
A2: Record_ID | B2: Month | C2: Channel | D2: Stage | E2: Users | F2: Prev_Stage_Users | G2: Conversion_Rate | H2: Revenue_INR | I2: Revenue_per_User_INR | J2: Drop_Off_Rate
A3: R0001 | B3: Jan 2024 | C3: Organic Search | D3: Website Visit | E3: 9618
A4: R0002 | B4: Jan 2024 | C4: Organic Search | D4: Landing Page | E4: 5447 | F4: 9618 | G4: 0.56633396 | J4: 0.43366604
A5: R0003 | B5: Jan 2024 | C5: Organic Search | D5: Signup | E5: 1501 | F5: 5447 | G5: 0.27556453 | J5: 0.72443547
A6: R0004 | B6: Jan 2024 | C6: Organic Search | D6: Product View | E6: 868 | F6: 1501 | G6: 0.57828115 | J6: 0.42171885
A7: R0005 | B7: Jan 2024 | C7: Organic Search | D7: Add to Cart | E7: 342 | F7: 868 | G7: 0.39400922 | J7: 0.60599078
A8: R0006 | B8: Jan 2024 | C8: Organic Search | D8: Checkout | E8: 219 | F8: 342 | G8: 0.64035088 | J8: 0.35964912
A9: R0007 | B9: Jan 2024 | C9: Organic Search | D9: Purchase | E9: 154 | F9: 219 | G9: 0.70319635 | H9: 565026 | I9: 3669 | J9: 0.29680365
A10: R0008 | B10: Jan 2024 | C10: Paid Ads | D10: Website Visit | E10: 11824
A11: R0009 | B11: Jan 2024 | C11: Paid Ads | D11: Landing Page | E11: 6744 | F11: 11824 | G11: 0.57036536 | J11: 0.42963464
A12: R0010 | B12: Jan 2024 | C12: Paid Ads | D12: Signup | E12: 1840 | F12: 6744 | G12: 0.27283511 | J12: 0.72716489
A13: R0011 | B13: Jan 2024 | C13: Paid Ads | D13: Product View | E13: 1275 | F13: 1840 | G13: 0.69293478 | J13: 0.30706522
A14: R0012 | B14: Jan 2024 | C14: Paid Ads | D14: Add to Cart | E14: 588 | F14: 1275 | G14: 0.46117647 | J14: 0.53882353
A15: R0013 | B15: Jan 2024 | C15: Paid Ads | D15: Checkout | E15: 383 | F15: 588 | G15: 0.65136054 | J15: 0.34863946
A16: R0014 | B16: Jan 2024 | C16: Paid Ads | D16: Purchase | E16: 291 | F16: 383 | G16: 0.75979112 | H16: 1212888 | I16: 4168 | J16: 0.24020888
A17: R0015 | B17: Jan 2024 | C17: Social Media | D17: Website Visit | E17: 9358
A18: R0016 | B18: Jan 2024 | C18: Social Media | D18: Landing Page | E18: 4703 | F18: 9358 | G18: 0.50256465 | J18: 0.49743535
A19: R0017 | B19: Jan 2024 | C19: Social Media | D19: Signup | E19: 1394 | F19: 4703 | G19: 0.29640655 | J19: 0.70359345
A20: R0018 | B20: Jan 2024 | C20: Social Media | D20: Product View | E20: 818 | F20: 1394 | G20: 0.58680057 | J20: 0.41319943
A21: R0019 | B21: Jan 2024 | C21: Social Media | D21: Add to Cart | E21: 375 | F21: 818 | G21: 0.45843521 | J21: 0.54156479
A22: R0020 | B22: Jan 2024 | C22: Social Media | D22: Checkout | E22: 196 | F22: 375 | G22: 0.52266667 | J22: 0.47733333
A23: R0021 | B23: Jan 2024 | C23: Social Media | D23: Purchase | E23: 146 | F23: 196 | G23: 0.74489796 | H23: 521804 | I23: 3574 | J23: 0.25510204
A24: R0022 | B24: Jan 2024 | C24: Email Campaign | D24: Website Visit | E24: 4438
A25: R0023 | B25: Jan 2024 | C25: Email Campaign | D25: Landing Page | E25: 2369 | F25: 4438 | G25: 0.53379901 | J25: 0.46620099
A26: R0024 | B26: Jan 2024 | C26: Email Campaign | D26: Signup | E26: 661 | F26: 2369 | G26: 0.27902068 | J26: 0.72097932
A27: R0025 | B27: Jan 2024 | C27: Email Campaign | D27: Product View | E27: 366 | F27: 661 | G27: 0.55370651 | J27: 0.44629349
A28: R0026 | B28: Jan 2024 | C28: Email Campaign | D28: Add to Cart | E28: 150 | F28: 366 | G28: 0.40983607 | J28: 0.59016393
A29: R0027 | B29: Jan 2024 | C29: Email Campaign | D29: Checkout | E29: 103 | F29: 150 | G29: 0.68666667 | J29: 0.31333333
A30: R0028 | B30: Jan 2024 | C30: Email Campaign | D30: Purchase | E30: 72 | F30: 103 | G30: 0.69902913 | H30: 193824 | I30: 2692 | J30: 0.30097087
A31: R0029 | B31: Jan 2024 | C31: Referral | D31: Website Visit | E31: 11497
A32: R0030 | B32: Jan 2024 | C32: Referral | D32: Landing Page | E32: 6523 | F32: 11497 | G32: 0.5673654 | J32: 0.4326346
A33: R0031 | B33: Jan 2024 | C33: Referral | D33: Signup | E33: 2236 | F33: 6523 | G33: 0.34278706 | J33: 0.65721294
A34: R0032 | B34: Jan 2024 | C34: Referral | D34: Product View | E34: 1391 | F34: 2236 | G34: 0.62209302 | J34: 0.37790698
A35: R0033 | B35: Jan 2024 | C35: Referral | D35: Add to Cart | E35: 572 | F35: 1391 | G35: 0.41121495 | J35: 0.58878505
A36: R0034 | B36: Jan 2024 | C36: Referral | D36: Checkout | E36: 386 | F36: 572 | G36: 0.67482517 | J36: 0.32517483
A37: R0035 | B37: Jan 2024 | C37: Referral | D37: Purchase | E37: 242 | F37: 386 | G37: 0.62694301 | H37: 978406 | I37: 4043 | J37: 0.37305699
A38: R0036 | B38: Jan 2024 | C38: Direct Traffic | D38: Website Visit | E38: 10237
A39: R0037 | B39: Jan 2024 | C39: Direct Traffic | D39: Landing Page | E39: 6445 | F39: 10237 | G39: 0.62957898 | J39: 0.37042102
A40: R0038 | B40: Jan 2024 | C40: Direct Traffic | D40: Signup | E40: 2190 | F40: 6445 | G40: 0.33979829 | J40: 0.66020171
...

Sheet Stage_Summary
A1: FUNNEL STAGE SUMMARY — All Channels Combined
A2: Funnel Stage | B2: Total Users | C2: Avg Conversion Rate | D2: Total Revenue (INR) | E2: Avg Revenue per User (INR) | F2: Avg Drop-Off Rate
A3: Website Visit | B3: =SUMIF(Funnel_Data!D3:D507,A3,Funnel_Data!E3:E507) -> 637580 | C3: =IFERROR(AVERAGEIF(Funnel_Data!D3:D507,A3,Funnel_Data!G3:G507),0) -> 0 | D3: =SUMIF(Funnel_Data!D3:D507,A3,Funnel_Data!H3:H507) -> 0 | E3: =IFERROR(AVERAGEIF(Funnel_Data!D3:D507,A3,Funnel_Data!I3:I507),0) -> 0 | F3: =IFERROR(AVERAGEIF(Funnel_Data!D3:D507,A3,Funnel_Data!J3:J507),0) -> 0
A4: Landing Page | B4: =SUMIF(Funnel_Data!D3:D507,A4,Funnel_Data!E3:E507) -> 348309 | C4: =IFERROR(AVERAGEIF(Funnel_Data!D3:D507,A4,Funnel_Data!G3:G507),0) -> 0.54435086 | D4: =SUMIF(Funnel_Data!D3:D507,A4,Funnel_Data!H3:H507) -> 0 | E4: =IFERROR(AVERAGEIF(Funnel_Data!D3:D507,A4,Funnel_Data!I3:I507),0) -> 0 | F4: =IFERROR(AVERAGEIF(Funnel_Data!D3:D507,A4,Funnel_Data!J3:J507),0) -> 0.45564914
A5: Signup | B5: =SUMIF(Funnel_Data!D3:D507,A5,Funnel_Data!E3:E507) -> 102994 | C5: =IFERROR(AVERAGEIF(Funnel_Data!D3:D507,A5,Funnel_Data!G3:G507),0) -> 0.29606897 | D5: =SUMIF(Funnel_Data!D3:D507,A5,Funnel_Data!H3:H507) -> 0 | E5: =IFERROR(AVERAGEIF(Funnel_Data!D3:D507,A5,Funnel_Data!I3:I507),0) -> 0 | F5: =IFERROR(AVERAGEIF(Funnel_Data!D3:D507,A5,Funnel_Data!J3:J507),0) -> 0.70393103
A6: Product View | B6: =SUMIF(Funnel_Data!D3:D507,A6,Funnel_Data!E3:E507) -> 66429 | C6: =IFERROR(AVERAGEIF(Funnel_Data!D3:D507,A6,Funnel_Data!G3:G507),0) -> 0.6472414 | D6: =SUMIF(Funnel_Data!D3:D507,A6,Funnel_Data!H3:H507) -> 0 | E6: =IFERROR(AVERAGEIF(Funnel_Data!D3:D507,A6,Funnel_Data!I3:I507),0) -> 0 | F6: =IFERROR(AVERAGEIF(Funnel_Data!D3:D507,A6,Funnel_Data!J3:J507),0) -> 0.3527586
A7: Add to Cart | B7: =SUMIF(Funnel_Data!D3:D507,A7,Funnel_Data!E3:E507) -> 29069 | C7: =IFERROR(AVERAGEIF(Funnel_Data!D3:D507,A7,Funnel_Data!G3:G507),0) -> 0.43904264 | D7: =SUMIF(Funnel_Data!D3:D507,A7,Funnel_Data!H3:H507) -> 0 | E7: =IFERROR(AVERAGEIF(Funnel_Data!D3:D507,A7,Funnel_Data!I3:I507),0) -> 0 | F7: =IFERROR(AVERAGEIF(Funnel_Data!D3:D507,A7,Funnel_Data!J3:J507),0) -> 0.56095736
A8: Checkout | B8: =SUMIF(Funnel_Data!D3:D507,A8,Funnel_Data!E3:E507) -> 17361 | C8: =IFERROR(AVERAGEIF(Funnel_Data!D3:D507,A8,Funnel_Data!G3:G507),0) -> 0.59963376 | D8: =SUMIF(Funnel_Data!D3:D507,A8,Funnel_Data!H3:H507) -> 0 | E8: =IFERROR(AVERAGEIF(Funnel_Data!D3:D507,A8,Funnel_Data!I3:I507),0) -> 0 | F8: =IFERROR(AVERAGEIF(Funnel_Data!D3:D507,A8,Funnel_Data!J3:J507),0) -> 0.40036624
A9: Purchase | B9: =SUMIF(Funnel_Data!D3:D507,A9,Funnel_Data!E3:E507) -> 12084 | C9: =IFERROR(AVERAGEIF(Funnel_Data!D3:D507,A9,Funnel_Data!G3:G507),0) -> 0.69356603 | D9: =SUMIF(Funnel_Data!D3:D507,A9,Funnel_Data!H3:H507) -> 32478487 | E9: =IFERROR(AVERAGEIF(Funnel_Data!D3:D507,A9,Funnel_Data!I3:I507),0) -> 2593.5972 | F9: =IFERROR(AVERAGEIF(Funnel_Data!D3:D507,A9,Funnel_Data!J3:J507),0) -> 0.30643397

Sheet Channel_Performance
A1: CHANNEL PERFORMANCE SUMMARY
A2: Channel | B2: Total Website Visits | C2: Total Purchases | D2: Overall Conversion Rate | E2: Total Revenue (INR) | F2: Avg Order Value (INR)
A3: Organic Search | B3: =SUMIFS(Funnel_Data!E3:E507,Funnel_Data!C3:C507,A3,Funnel_Data!D3:D507,"Website Visit") -> 91928 | C3: =SUMIFS(Funnel_Data!E3:E507,Funnel_Data!C3:C507,A3,Funnel_Data!D3:D507,"Purchase") -> 1740 | D3: =IF(B3>0,C3/B3,0) -> 0.018927857 | E3: =SUMIFS(Funnel_Data!H3:H507,Funnel_Data!C3:C507,A3) -> 4561344 | F3: =IF(C3>0,E3/C3,0) -> 2621.4621
A4: Paid Ads | B4: =SUMIFS(Funnel_Data!E3:E507,Funnel_Data!C3:C507,A4,Funnel_Data!D3:D507,"Website Visit") -> 126167 | C4: =SUMIFS(Funnel_Data!E3:E507,Funnel_Data!C3:C507,A4,Funnel_Data!D3:D507,"Purchase") -> 2477 | D4: =IF(B4>0,C4/B4,0) -> 0.019632709 | E4: =SUMIFS(Funnel_Data!H3:H507,Funnel_Data!C3:C507,A4) -> 8174205 | F4: =IF(C4>0,E4/C4,0) -> 3300.0424
A5: Social Media | B5: =SUMIFS(Funnel_Data!E3:E507,Funnel_Data!C3:C507,A5,Funnel_Data!D3:D507,"Website Visit") -> 113512 | C5: =SUMIFS(Funnel_Data!E3:E507,Funnel_Data!C3:C507,A5,Funnel_Data!D3:D507,"Purchase") -> 1986 | D5: =IF(B5>0,C5/B5,0) -> 0.017495948 | E5: =SUMIFS(Funnel_Data!H3:H507,Funnel_Data!C3:C507,A5) -> 3520472 | F5: =IF(C5>0,E5/C5,0) -> 1772.6445
A6: Email Campaign | B6: =SUMIFS(Funnel_Data!E3:E507,Funnel_Data!C3:C507,A6,Funnel_Data!D3:D507,"Website Visit") -> 94492 | C6: =SUMIFS(Funnel_Data!E3:E507,Funnel_Data!C3:C507,A6,Funnel_Data!D3:D507,"Purchase") -> 1834 | D6: =IF(B6>0,C6/B6,0) -> 0.019409051 | E6: =SUMIFS(Funnel_Data!H3:H507,Funnel_Data!C3:C507,A6) -> 4540909 | F6: =IF(C6>0,E6/C6,0) -> 2475.9591
A7: Referral | B7: =SUMIFS(Funnel_Data!E3:E507,Funnel_Data!C3:C507,A7,Funnel_Data!D3:D507,"Website Visit") -> 109333 | C7: =SUMIFS(Funnel_Data!E3:E507,Funnel_Data!C3:C507,A7,Funnel_Data!D3:D507,"Purchase") -> 2033 | D7: =IF(B7>0,C7/B7,0) -> 0.018594569 | E7: =SUMIFS(Funnel_Data!H3:H507,Funnel_Data!C3:C507,A7) -> 7020428 | F7: =IF(C7>0,E7/C7,0) -> 3453.2356
A8: Direct Traffic | B8: =SUMIFS(Funnel_Data!E3:E507,Funnel_Data!C3:C507,A8,Funnel_Data!D3:D507,"Website Visit") -> 102148 | C8: =SUMIFS(Funnel_Data!E3:E507,Funnel_Data!C3:C507,A8,Funnel_Data!D3:D507,"Purchase") -> 2014 | D8: =IF(B8>0,C8/B8,0) -> 0.01971649 | E8: =SUMIFS(Funnel_Data!H3:H507,Funnel_Data!C3:C507,A8) -> 4661129 | F8: =IF(C8>0,E8/C8,0) -> 2314.364
A9: TOTAL | B9: =SUM(B3:B8) -> 637580 | C9: =SUM(C3:C8) -> 12084 | D9: =IF(B9>0,C9/B9,0) -> 0.018952916 | E9: =SUM(E3:E8) -> 32478487 | F9: =IF(C9>0,E9/C9,0) -> 2687.7265

Sheet KPI_Dashboard
A1: CUSTOMER JOURNEY KPI DASHBOARD
A2: KPI Metric | B2: Value | C2: Formula Reference | D2: Business Insight
A3: Total Unique Visitors | B3: =SUMIFS(Funnel_Data!E3:E507,Funnel_Data!D3:D507,"Website Visit") -> 637580 | C3: =SUMIFS(Funnel_Data!E3:E507,Funnel_Data!D3:D507,"Website Visit") -> 637580 | D3: Total top-of-funnel traffic
A4: Total Signups | B4: =SUMIFS(Funnel_Data!E3:E507,Funnel_Data!D3:D507,"Signup") -> 102994 | C4: =SUMIFS(Funnel_Data!E3:E507,Funnel_Data!D3:D507,"Signup") -> 102994 | D4: Users who signed up
A5: Total Purchases | B5: =SUMIFS(Funnel_Data!E3:E507,Funnel_Data!D3:D507,"Purchase") -> 12084 | C5: =SUMIFS(Funnel_Data!E3:E507,Funnel_Data!D3:D507,"Purchase") -> 12084 | D5: Converted customers
A6: Overall Conv. Rate (Visit→Purchase) | B6: =IF(B3>0,B5/B3,0) -> 0.018952916 | C6: =IF(B3>0,B5/B3,0) -> 0.018952916 | D6: End-to-end conversion %
A7: Total Revenue (INR) | B7: =SUM(Funnel_Data!H3:H507) -> 32478487 | C7: =SUM(Funnel_Data!H3:H507) -> 32478487 | D7: Total funnel revenue
A8: Avg Order Value (INR) | B8: =IF(B5>0,B7/B5,0) -> 2687.7265 | C8: =IF(B5>0,B7/B5,0) -> 2687.7265 | D8: Revenue per purchase
A9: Avg Signup Conv. Rate | B9: =AVERAGEIFS(Funnel_Data!G3:G507,Funnel_Data!D3:D507,"Signup") -> 0.29606897 | C9: =AVERAGEIFS(Funnel_Data!G3:G507,Funnel_Data!D3:D507,"Signup") -> 0.29606897 | D9: Visit to Signup rate
A10: Avg Purchase Conv. Rate | B10: =AVERAGEIFS(Funnel_Data!G3:G507,Funnel_Data!D3:D507,"Purchase") -> 0.69356603 | C10: =AVERAGEIFS(Funnel_Data!G3:G507,Funnel_Data!D3:D507,"Purchase") -> 0.69356603 | D10: Checkout to Purchase rate
A11: Best Performing Channel | B11: =INDEX(Channel_Performance!A3:A9,MATCH(MAX(Channel_Performance!E3:E9),Channel_Performance!E3:E9,0)) -> TOTAL | C11: =INDEX(Channel_Performance!A3:A9,MATCH(MAX(Channel_Performance!E3:E9),Channel_Performance!E3:E9,0)) -> TOTAL | D11: Channel generating most revenue
A12: Total Active Months | B12: =12 -> 12 | C12: =12 -> 12 | D12: Months of data covered
